
### try-catch

예외 처리란, 프로그램 실행 시  발생할 수 있는 예기치 못한 예외의 발생에 대비한 코드를 작성하는 것이다. 예외 처리의 목적은 예외 발생으로 인한 실행 중인 프로그램의 갑작스런 비정상 종류를 막고, 정상적인 실행상태를 유지할 수 있도록 하는 것이다.

발생한 예외를 처리하지 못하면, 프로그램은 비정상적으로 종료되며, 처리되지 못한 예외는 JVM 예외처리기가 받아서 예외 원인을 화면에 출력한다.

에외를 처리하기 위해서는 `try-catch` 문을 사용하면 된다.

```
private static String[] informations = {"jxx", "30"};  
  
public static String getInformation(int idx) {  
    String information;  
    try {  
        information = informations[idx];  
    } catch (ArrayIndexOutOfBoundsException e) {  
		// ArrayIndexOutOfBoundsException 예외가 발생했을 때 처리
        return String.format("0 ~ %d 사이의 값을 입력해주세요", informations.length - 1);  
    }  
    return information;  
}
```



```
public static void main(String[] args) {  
    for (int i = -1; i < 2; i++) {  
        String information = getInformation(i);  
        System.out.println(information);  
    }  
}
```

예외 처리를 하지 않았다면 for 루프에서 `i = -1`  일 때  배열의 범위가 벗어나므로 `ArrayIndexOutOfBoundsException` 가 발생하며 프로그램이 종료된다. 하지만 예외 처리를 해주었기 때문에 아래와 같은 출력 결과가 나오게 된다.

```
0 ~ 1 사이의 값을 입력해주세요
jxx
30
```


### try-catch문에서의 흐름

`try-catch` 문에서, 예외가 발생한 경우와 발생하지 않았을 때의 흐름이 달라진다. 


##### try 블랙 내에서 예외가 발생한 경우,
1. 발생한 예외와 일치하는 `catch` 블럭이 있는지 확인한다. 예외가 발생하는 순간 `try` **블럭에 남은 소스 코드는 수행되지 않는다**.  
2. 일치하는 `catch` 블럭을 찾게 되면, 그 `catch` 블럭 내의 문장들을 수행하고 전체 `try-catch` 문을 빠져나가서 **그 다음 문장을 계속해서 수행한다**. 만일 일치하는 catch 블럭을 찾지 못하면, 예외는 처리되지 못한다. **즉, 그 다음 문장을 수행하지 못한다**.

##### try 블럭 내에서 예외가 발생하지 않는 경우,
1. catch 블럭을 거치지 않고 전체 `try-catch`  문을 빠져나가서 수행을 계속한다.


*참고 : try 블럭에서 예외가 발생했을 때, try 블럭의 남은 코드들은 실행될까?*

예외가 발생하면  `try` 블럭 내 예외가 발생한 지점보다 하단에 있는 소스 코드는 수행되지 않는다고 했다. 코드와 주석을 통해 이를 이해해보자.

```
try {  
    information = informations[idx];  // idx 에 음수가 들어와 예외가 발생
    System.out.printf("information %s 예외가 발생하지 않았습니다.", information);  // 예외가 발생했기 때문에 수행되지 않음
} catch (ArrayIndexOutOfBoundsException e) {  
    return String.format("0 ~ %d 사이의 값을 입력해주세요", informations.length - 1);  
}
```



### 예외 발생과 catch 블럭


```
catch (ArrayIndexOutOfBoundsException e) {  
    return String.format("0 ~ %d 사이의 값을 입력해주세요", informations.length - 1);  
}
```


`catch` 블럭은 `괄호()` , `블럭{}` 두 부분으로 나눠져 있다.

`괄호()` 내에는 처리하고자 하는 예외와 같은 타입의 참조변수 하나를 선언해야 한다. 예외가 발생하면 **발생한 예외에 해당하는** 클래스의 인스턴스가 만들어 진다.


*참고 : 예외 발생 시 만들어지는 예외 클래스 확인해보기*
```
catch (Exception e) {  
    System.out.printf("Exception Type : %s", e.getClass());  
    return String.format("0 ~ %d 사이의 값을 입력해주세요", informations.length - 1);  
}

// 결과 Exception Type : class java.lang.ArrayIndexOutOfBoundsException
```

catch 문의 괄호에 인자로 Exception 타입을 넣더라도 만들어지는 인스턴스는 `ArrayIndexOutOfBoundsException` 인 것을 통해 이를 확인할 수 있다.

---

이렇게 예외가 발생하고, 예외 클래스 인스턴스도 만들어지게 되면 `catch` 블럭을 차례로 내려가면서 `catch` 블럭 괄호 내에 선언된 참조 변수의 종류와 생성된 예외 클래스의 인스턴스에 `instanceof` 연산자를 이용해서 검사한다. 검사 결과가 `true`인 `catch` 블럭을 만날 때까지 검사는 계속된다. 

이를 코드로 표현해보면 아래와 같다.

```
// 만들어진 예외 클래스 ArrayIndexOutOfBoundsException
catch (예외1 e1) { 
   // ArrayIndexOutOfBoundsException isntanceof e1 수행 결과 : false -> 다음 catch 블록으로 이동
  // 예외 처리
}
catch (예외2 e2) { 
  // ArrayIndexOutOfBoundsException isntanceof e1 수행 결과 : true -> 아래 예외 처리 구문 실행
  // 예외 처리
}
```


그리고 만약 `instanceof` 검사 결과가 모두 `false` 라면 예외는 처리되지 않는다.


#### `printStackTrace()`, `getMessage()


```
prinStackTrace() : 예외발생 당시의 호출스택(Call Stack)에 있었던 메서드의 정보와 예외 메시지를 화면에 출력
getMessage() : 발생한 예외클래스의 인스턴스에 저장된 메시지를 얻을 수 있음
```


`prinStackTrace()` 의 경우에는 예외의 발생원인을 알기 좋은 메서드이다. 다만, 실제 프로덕트 환경에서는 `prinStackTrace()` 를 사용자에게 노출시키는 일은 피하는 것이 바람직해보인다.


#### 멀티 catch 블럭

JDK1.7 부터 지원되는 문법이다.

```
catch(Exception1 | Exception2 e) {
 // 예외 처리
}
```

멀티 catch 블럭을 사용할 경우, 연속적으로 나열되는 `catch`  구문을 피할 수 있어 가독성이 높아진다. 다만 어떤 예외가 발생했는지는 `e.getClass()` 와 같이 직접 호출하지 않는 이상 파악하기 어렵다는 단점이 있다.

